use std::num::ParseIntError;

fn multiply(first_number_str: &str, second_number_str: &str) -> Result<i32, ParseIntError> {
    first_number_str.parse::<i32>().and_then(|first_number| {
        second_number_str
            .parse::<i32>()
            .map(|secon_number| first_number * secon_number)
    })
}

fn print(result: Result<i32, ParseIntError>) {
    match result {
        Ok(n) => println!("n is {}", n),
        Err(e) => println!("Error: {}", e),
    }
}

fn main() {
    // This still presents a reasonable answer.
    let twenty = multiply("10", "2");
    print(twenty);

    // The following now provides a much more helpful error message.
    let tt = multiply("t", "2");
    print(tt);
}
